package test02_try_catch;

public class ExceptionTest1 {
	public static void main(String[] args) {
		int[] nums = {10};
		
		// try ... catch
		// 1.  예외가 발생했고 성공적으로 처리되었을 때(catch문을 만났을 때): 1 (2) 4 5
		// 2. 예외가 발생했는데 성공적으로 처리되지 못했을 때(catch 문을 못 만났을 때) 1 (2-비정상적 종료)
		// 3. 예외가 발생하지 않았을 때: 1 2 3 5
		try {
			System.out.println("정상 코드 1");	// (1) 정상 코드
//			System.out.println(nums[2]);	// (2) 예외 발생 가능한 코드
			System.out.println("정상 코드 2");// (3) 정상 코드
		} catch(ArithmeticException e) {
			// catch문에서 매개변수 타입으로 정한 예외와 일치하거나 그 자손일 때
			// Exception => 모든 예외 처리 가능.
			System.out.println("배열의 인덱스 범위를 벗어났어요. "); // (4) 예외처리 코드
		}
		System.out.println("프로그램 종료"); // (5) 정상 코드
	}
}
